<mujoco>
            <option gravity="0 0 -15" />
            <worldbody>
                <light diffuse=".5 .5 .6" pos="0 2 3" dir="0 -0.5 -1" />
                <geom type="plane" size="3 3 0.1" rgba="0.8 0.8 0.8 1" />
                <body name="body" pos="0 0 1" euler="0 90 0">
	<joint type="free" />
	<geom type="sphere" size="0.27 0.27 0.27" rgba="1.35 0.9 0.3 1.0" />
	<body name="leg0" pos="0 0 -0.55" euler="0 0 0">
		<joint name="leg0_joint" type="hinge" pos="0 0 0.28" axis="0 90 0" range="-45 45" />
		<geom type="box" size="0.1 0.1 0.28" rgba="1.4 0.5 0.75 1.0" />
	<body name="leg0_seg1" pos="0 0 -0.56" euler="0 0 0">
		<joint name="leg0_seg1_joint" type="hinge" pos="0 0 0.28" axis="0 90 0" range="-45 45" />
		<geom type="box" size="0.1 0.1 0.28" rgba="1.4 0.5 0.75 1.0" />
	</body>
	</body>
	<body name="leg1" pos="0 0.55 0" euler="90 0 0">
		<joint name="leg1_joint" type="hinge" pos="0 0 0.28" axis="0 90 0" range="-53 53" />
		<geom type="box" size="0.1 0.1 0.28" rgba="1.4 0.5 0.75 1.0" />
	<body name="leg1_seg1" pos="0 0 -0.56" euler="0 0 0">
		<joint name="leg1_seg1_joint" type="hinge" pos="0 0 0.28" axis="0 90 0" range="-53 53" />
		<geom type="box" size="0.1 0.1 0.28" rgba="1.4 0.5 0.75 1.0" />
	</body>
	</body>
	<body name="leg2" pos="0 0 0.55" euler="180 0 0">
		<joint name="leg2_joint" type="hinge" pos="0 0 0.28" axis="0 90 0" range="-47 47" />
		<geom type="box" size="0.1 0.1 0.28" rgba="1.35 0.9 0.3 1.0" />
	<body name="leg2_seg1" pos="0 0 -0.56" euler="0 0 0">
		<joint name="leg2_seg1_joint" type="hinge" pos="0 0 0.28" axis="0 90 0" range="-47 47" />
		<geom type="box" size="0.1 0.1 0.28" rgba="0.4 0.7 1.5 1.0" />
	</body>
	</body>
</body>
            </worldbody>
                <actuator>
                    <motor gear="42" joint="leg0_joint" />
<motor gear="49" joint="leg1_joint" />
<motor gear="32" joint="leg2_joint" />

                </actuator>
        </mujoco>