<mujoco>
<option gravity="0 0 -25"/>
	<worldbody>
        <light diffuse=".5 .5 .5" pos="0 0 3" dir="0 0 -1"/>
		<geom type="plane" size="2 2 0.1" rgba="0.5 0.5 1 1"/>
        <body name="border" pos="0 0 0"/>
            <geom name="border1" pos="2 0 0.1" type="box" size="0.05 2 0.15" rgba="0.5 0.5 1 1"/>
            <geom name="border2" pos="-2 0 0.1" type="box" size="0.05 2 0.15" rgba="0.5 0.5 1 1"/>
            <geom name="border3" pos="0 2 0.1" type="box" size="0.05 2 0.15" rgba="0.5 0.5 1 1" euler="0 0 90"/>
            <geom name="border4" pos="0 -2 0.1" type="box" size="0.05 2 0.15" rgba="0.5 0.5 1 1" euler="0 0 90"/>

        <body name="body1" pos="0 0 0.5" euler="0 90 0">
			<joint name="joint1" type="free" axis="0.3 0.5 0" pos="0 0 0" range="-50 50"/>
            <geom name="head" type="sphere" size="0.05" rgba="1 0 1 1" euler="0.1 0.1 0"/>
            <body pos="0 0 -0.2" euler="0 0 0">
                <joint name="joint2" type="hinge" axis="0.3 0 0" pos="0 0 0" range="-10 10"/>
			    <geom name="seg2" type="capsule" size="0.05 .05" rgba="1 1 1 1" euler="0.1 0.1 0"/>
                <body pos="0 0 -0.2" euler="0 0 0">
                    <joint name="joint3" type="hinge" axis="0.3 0 0" pos="0 0 0" range="-10 10"/>
                    <geom name="seg3" type="capsule" size="0.05 .05" rgba="1 0 1 1" euler="0.1 0.1 0"/>
                    <body pos="0 0 -0.2" euler="0 0 0">
                        <joint name="joint4" type="hinge" axis="0.3 0 0" pos="0 0 0" range="-10 10"/>
                        <geom name="seg4" type="capsule" size="0.05 .05" rgba="1 1 1 1" euler="0.1 0.1 0"/>
                        <body pos="0 0 -0.2" euler="0 0 0">
                            <joint name="joint5" type="hinge" axis="0.3 0 0" pos="0 0 0" range="-10 10"/>
                            <geom name="tail" type="capsule" size="0.05 .03" rgba="1 0 1 1" euler="0.1 0.1 0"/>
                        </body>
                    </body>
                </body>
            </body>
		</body>
	</worldbody>
    <actuator>
        <motor name="hinge1" gear="30" joint="joint1"/>
        <motor name="hinge2" gear="10" joint="joint2"/>
        <motor name="hinge3" gear="10" joint="joint3"/>
        <motor name="hinge4" gear="10" joint="joint4"/>
    </actuator> 
</mujoco>
