<mujoco><option gravity="0 0 -30" /><worldbody><light diffuse="0.5 0.5 0.6" pos="0 2 3" dir="0 -0.5 -1" /><geom type="plane" size="5 5 0.1" rgba="0.8 0.8 0.8 1" /><body name="mainbody" pos="0 0 1" euler="0 90 0"><joint type="free" /><geom type="box" size="0.28 0.28 0.28" rgba="1.35 0.9 0.3 1.0" /><body name="leg0" pos="0 0 0.56" euler="180 0 0"><joint name="leg0_joint" type="hinge" pos="0 0 0.28" axis="0 90 0" range="-51 51" /><geom type="cylinder" size="0.12 0.28 0.28" rgba="1.4 0.5 0.75 1.0" /><body name="leg0_seg0" pos="0 0 -0.56" euler="0 0 0"><joint name="leg0_seg0_joint" type="hinge" pos="0 0 0.28" axis="0 90 0" range="-51 51" /><geom type="cylinder" size="0.12 0.28 0.28" rgba="1.4 0.5 0.75 1.0" /><body name="leg0_seg1" pos="0 0 -0.56" euler="0 0 0"><joint name="leg0_seg1_joint" type="hinge" pos="0 0 0.28" axis="0 90 0" range="-51 51" /><geom type="cylinder" size="0.12 0.28 0.28" rgba="1.4 0.5 0.75 1.0" /><body name="leg0_seg2" pos="0 0 -0.56" euler="0 0 0"><joint name="leg0_seg2_joint" type="hinge" pos="0 0 0.28" axis="0 90 0" range="-51 51" /><geom type="cylinder" size="0.12 0.28 0.28" rgba="1.4 0.5 0.75 1.0" /></body></body></body></body><body name="leg1" pos="0 -0.56 0" euler="-90 0 0"><joint name="leg1_joint" type="hinge" pos="0 0 0.28" axis="0 90 0" range="-76 76" /><geom type="cylinder" size="0.12 0.28 0.28" rgba="1.4 0.5 0.75 1.0" /><body name="leg1_seg0" pos="0 0 -0.56" euler="0 0 0"><joint name="leg1_seg0_joint" type="hinge" pos="0 0 0.28" axis="0 90 0" range="-76 76" /><geom type="cylinder" size="0.12 0.28 0.28" rgba="1.4 0.5 0.75 1.0" /><body name="leg1_seg1" pos="0 0 -0.56" euler="0 0 0"><joint name="leg1_seg1_joint" type="hinge" pos="0 0 0.28" axis="0 90 0" range="-76 76" /><geom type="cylinder" size="0.12 0.28 0.28" rgba="1.4 0.5 0.75 1.0" /><body name="leg1_seg2" pos="0 0 -0.56" euler="0 0 0"><joint name="leg1_seg2_joint" type="hinge" pos="0 0 0.28" axis="0 90 0" range="-76 76" /><geom type="cylinder" size="0.12 0.28 0.28" rgba="1.4 0.5 0.75 1.0" /></body></body></body></body><body name="leg2" pos="0 0.56 0" euler="90 0 0"><joint name="leg2_joint" type="hinge" pos="0 0 0.28" axis="0 90 0" range="-73 73" /><geom type="cylinder" size="0.12 0.28 0.28" rgba="1.4 0.5 0.75 1.0" /><body name="leg2_seg0" pos="0 0 -0.56" euler="0 0 0"><joint name="leg2_seg0_joint" type="hinge" pos="0 0 0.28" axis="0 90 0" range="-73 73" /><geom type="cylinder" size="0.12 0.28 0.28" rgba="1.4 0.5 0.75 1.0" /><body name="leg2_seg1" pos="0 0 -0.56" euler="0 0 0"><joint name="leg2_seg1_joint" type="hinge" pos="0 0 0.28" axis="0 90 0" range="-73 73" /><geom type="cylinder" size="0.12 0.28 0.28" rgba="1.4 0.5 0.75 1.0" /><body name="leg2_seg2" pos="0 0 -0.56" euler="0 0 0"><joint name="leg2_seg2_joint" type="hinge" pos="0 0 0.28" axis="0 90 0" range="-73 73" /><geom type="cylinder" size="0.12 0.28 0.28" rgba="1.4 0.5 0.75 1.0" /></body></body></body></body><body name="leg3" pos="0 0 0.56" euler="180 0 0"><joint name="leg3_joint" type="hinge" pos="0 0 0.28" axis="0 90 0" range="-42 42" /><geom type="cylinder" size="0.12 0.28 0.28" rgba="1.35 0.9 0.3 1.0" /><body name="leg3_seg0" pos="0 0 -0.56" euler="0 0 0"><joint name="leg3_seg0_joint" type="hinge" pos="0 0 0.28" axis="0 90 0" range="-42 42" /><geom type="cylinder" size="0.12 0.28 0.28" rgba="1.35 0.9 0.3 1.0" /><body name="leg3_seg1" pos="0 0 -0.56" euler="0 0 0"><joint name="leg3_seg1_joint" type="hinge" pos="0 0 0.28" axis="0 90 0" range="-42 42" /><geom type="cylinder" size="0.12 0.28 0.28" rgba="1.35 0.9 0.3 1.0" /><body name="leg3_seg2" pos="0 0 -0.56" euler="0 0 0"><joint name="leg3_seg2_joint" type="hinge" pos="0 0 0.28" axis="0 90 0" range="-42 42" /><geom type="cylinder" size="0.12 0.28 0.28" rgba="1.35 0.9 0.3 1.0" /></body></body></body></body><body name="leg4" pos="0 0 0.56" euler="180 0 0"><joint name="leg4_joint" type="hinge" pos="0 0 0.28" axis="0 90 0" range="-64 64" /><geom type="cylinder" size="0.12 0.28 0.28" rgba="0.4 0.7 1.5 1.0" /><body name="leg4_seg0" pos="0 0 -0.56" euler="0 0 0"><joint name="leg4_seg0_joint" type="hinge" pos="0 0 0.28" axis="0 90 0" range="-64 64" /><geom type="cylinder" size="0.12 0.28 0.28" rgba="0.4 0.7 1.5 1.0" /><body name="leg4_seg1" pos="0 0 -0.56" euler="0 0 0"><joint name="leg4_seg1_joint" type="hinge" pos="0 0 0.28" axis="0 90 0" range="-64 64" /><geom type="cylinder" size="0.12 0.28 0.28" rgba="0.4 0.7 1.5 1.0" /><body name="leg4_seg2" pos="0 0 -0.56" euler="0 0 0"><joint name="leg4_seg2_joint" type="hinge" pos="0 0 0.28" axis="0 90 0" range="-64 64" /><geom type="cylinder" size="0.12 0.28 0.28" rgba="0.4 0.7 1.5 1.0" /></body></body></body></body><body name="leg5" pos="0 0.56 0" euler="90 0 0"><joint name="leg5_joint" type="hinge" pos="0 0 0.28" axis="0 90 0" range="-77 77" /><geom type="cylinder" size="0.12 0.28 0.28" rgba="1.35 0.9 0.3 1.0" /><body name="leg5_seg0" pos="0 0 -0.56" euler="0 0 0"><joint name="leg5_seg0_joint" type="hinge" pos="0 0 0.28" axis="0 90 0" range="-77 77" /><geom type="cylinder" size="0.12 0.28 0.28" rgba="1.35 0.9 0.3 1.0" /><body name="leg5_seg1" pos="0 0 -0.56" euler="0 0 0"><joint name="leg5_seg1_joint" type="hinge" pos="0 0 0.28" axis="0 90 0" range="-77 77" /><geom type="cylinder" size="0.12 0.28 0.28" rgba="1.35 0.9 0.3 1.0" /><body name="leg5_seg2" pos="0 0 -0.56" euler="0 0 0"><joint name="leg5_seg2_joint" type="hinge" pos="0 0 0.28" axis="0 90 0" range="-77 77" /><geom type="cylinder" size="0.12 0.28 0.28" rgba="1.35 0.9 0.3 1.0" /></body></body></body></body><body name="leg6" pos="-0.56 0 0" euler="0 90 0"><joint name="leg6_joint" type="hinge" pos="0 0 0.28" axis="0 90 0" range="-57 57" /><geom type="cylinder" size="0.12 0.28 0.28" rgba="0.4 0.7 1.5 1.0" /><body name="leg6_seg0" pos="0 0 -0.56" euler="0 0 0"><joint name="leg6_seg0_joint" type="hinge" pos="0 0 0.28" axis="0 90 0" range="-57 57" /><geom type="cylinder" size="0.12 0.28 0.28" rgba="0.4 0.7 1.5 1.0" /><body name="leg6_seg1" pos="0 0 -0.56" euler="0 0 0"><joint name="leg6_seg1_joint" type="hinge" pos="0 0 0.28" axis="0 90 0" range="-57 57" /><geom type="cylinder" size="0.12 0.28 0.28" rgba="0.4 0.7 1.5 1.0" /><body name="leg6_seg2" pos="0 0 -0.56" euler="0 0 0"><joint name="leg6_seg2_joint" type="hinge" pos="0 0 0.28" axis="0 90 0" range="-57 57" /><geom type="cylinder" size="0.12 0.28 0.28" rgba="0.4 0.7 1.5 1.0" /></body></body></body></body><body name="leg7" pos="-0.56 0 0" euler="0 90 0"><joint name="leg7_joint" type="hinge" pos="0 0 0.28" axis="0 90 0" range="-37 37" /><geom type="cylinder" size="0.12 0.28 0.28" rgba="0.4 0.7 1.5 1.0" /><body name="leg7_seg0" pos="0 0 -0.56" euler="0 0 0"><joint name="leg7_seg0_joint" type="hinge" pos="0 0 0.28" axis="0 90 0" range="-37 37" /><geom type="cylinder" size="0.12 0.28 0.28" rgba="0.4 0.7 1.5 1.0" /><body name="leg7_seg1" pos="0 0 -0.56" euler="0 0 0"><joint name="leg7_seg1_joint" type="hinge" pos="0 0 0.28" axis="0 90 0" range="-37 37" /><geom type="cylinder" size="0.12 0.28 0.28" rgba="0.4 0.7 1.5 1.0" /><body name="leg7_seg2" pos="0 0 -0.56" euler="0 0 0"><joint name="leg7_seg2_joint" type="hinge" pos="0 0 0.28" axis="0 90 0" range="-37 37" /><geom type="cylinder" size="0.12 0.28 0.28" rgba="0.4 0.7 1.5 1.0" /></body></body></body></body></body></worldbody><actuator><motor gear="84" joint="leg0_joint" /><motor gear="104" joint="leg1_joint" /><motor gear="101" joint="leg2_joint" /><motor gear="87" joint="leg3_joint" /><motor gear="108" joint="leg4_joint" /><motor gear="109" joint="leg5_joint" /><motor gear="103" joint="leg6_joint" /><motor gear="106" joint="leg7_joint" /></actuator></mujoco>