<mujoco><option gravity="0 0 -50" /><worldbody><light diffuse="0.5 0.5 0.6" pos="0 2 3" dir="0 -0.5 -1" /><geom type="plane" size="5 5 0.1" rgba="0.8 0.8 0.8 1" /><body name="mainbody" pos="0 0 0.5" euler="0 90 0"><joint type="free" /><geom type="sphere" size="0.29000000000000004 0.29000000000000004 0.29000000000000004" rgba="0.4 0.7 1.5 1.0" /><body name="leg0" pos="-0.56 0 0" euler="0 90 0"><joint name="leg0_joint" type="hinge" pos="0 0 0.29" axis="0 90 0" range="-61 61" /><geom type="cylinder" size="0.13 0.29 0.29" rgba="0.4 0.7 1.5 1.0" /><body name="leg0_seg0" pos="0 0 -0.58" euler="0 0 0"><joint name="leg0_seg0_joint" type="hinge" pos="0 0 0.29" axis="0 90 0" range="-61 61" /><geom type="cylinder" size="0.13 0.29 0.29" rgba="0.4 0.7 1.5 1.0" /></body></body><body name="leg1" pos="0 0 -0.56" euler="0 0 0"><joint name="leg1_joint" type="hinge" pos="0 0 0.29" axis="0 90 0" range="-37 37" /><geom type="cylinder" size="0.13 0.29 0.29" rgba="0.4 0.7 1.5 1.0" /><body name="leg1_seg0" pos="0 0 -0.58" euler="0 0 0"><joint name="leg1_seg0_joint" type="hinge" pos="0 0 0.29" axis="0 90 0" range="-37 37" /><geom type="cylinder" size="0.13 0.29 0.29" rgba="0.4 0.7 1.5 1.0" /></body></body><body name="leg2" pos="0 0 -0.56" euler="0 0 0"><joint name="leg2_joint" type="hinge" pos="0 0 0.29" axis="0 90 0" range="-68 68" /><geom type="cylinder" size="0.13 0.29 0.29" rgba="0.4 0.7 1.5 1.0" /><body name="leg2_seg0" pos="0 0 -0.58" euler="0 0 0"><joint name="leg2_seg0_joint" type="hinge" pos="0 0 0.29" axis="0 90 0" range="-68 68" /><geom type="cylinder" size="0.13 0.29 0.29" rgba="0.4 0.7 1.5 1.0" /></body></body></body></worldbody><actuator><motor gear="100" joint="leg0_joint" /><motor gear="100" joint="leg1_joint" /><motor gear="100" joint="leg2_joint" /></actuator></mujoco>